<mujoco model="y">
  <default>
    <geom rgba=".8 .6 .4 1"  solref="0.02 1"/>
  </default>
  <option gravity="0 0 0"/>

  <asset>
    <texture type="skybox" builtin="gradient" rgb1="1 1 1" rgb2=".6 .8 1" width="256" height="256"/>
  </asset>

  <worldbody>
    <light pos="0 1 1" dir="0 -1 -1" diffuse="1 1 1"/>
    <body pos="0 0 0">
      <joint type="hinge" name="joint0" axis="0 1 0" limited="false" range="-120 120"/>
      <geom type="capsule" size="0.01" fromto="0 0 0  0 0 -0.1"/>
      <body pos="0 0.02 -0.1">
        <joint type="hinge" name="joint1" axis="0 0 1" limited="true" range="-120 120"/>
        <geom type="capsule" size="0.01" fromto="0 0 0  0 0.1 0"/>
          <body pos="0 0.12 0">
          <joint type="hinge" name="joint2" axis="0 1 0" limited="true" range="-120 120"/>
          <geom type="capsule" size="0.01" fromto="0 0 0  0 0 -0.1"/>
          <body pos="0 0 -0.12">
            <joint type="hinge" name="jnt_end0" axis="1 0 0" limited="true" range="-120 120"/>
            <geom type="capsule" size="0.01" fromto="0 0 0  0 0 -0.1"/>
            <body pos="0 0 -0.1"><site name="end0" type="sphere" size="0.01"/></body>
          </body>
        </body>
      </body>
      <body pos="0 -0.02 -0.1">
      <joint type="hinge" name="joint4" axis="1 0 0" limited="true" range="-120 120"/>
      <geom type="capsule" size="0.01" fromto="0 0 0  0 -0.1 0"/>
        <body pos="0 -0.12 0">
        <joint type="hinge" name="joint5" axis="0 1 0" limited="true" range="-120 120"/>
        <geom type="capsule" size="0.01" fromto="0 0 0  0 0 -0.1"/>
          <body pos="0 0 -0.12">
          <joint type="hinge" name="jnt_end1" axis="1 0 0" limited="true" range="-120 120"/>
          <geom type="capsule" size="0.01" fromto="0 0 0  0 0 -0.1"/>
          <body pos="0 0 -0.1"><site name="end1" type="sphere" size="0.01"/></body>
        </body>
      </body>
      </body>
    </body>

  </worldbody>

  <worldbody>
    <body pos="-0.1 0.2 0.2">
      <joint type="free" name="t0"/>
      <geom type="sphere" size="0.01" rgba="1 0 0 1" name="target0" contype="0" conaffinity="2"/>
    </body>
  </worldbody>

  <worldbody>
    <body pos="0.0 0.2 0.1">
      <joint type="free" name="t1"/>
      <geom type="sphere" size="0.01" rgba="1 0 0 1" name="target1" contype="0" conaffinity="2"/>
    </body>
  </worldbody>

  <actuator>
    <motor name="joint0act" joint="joint0"/>
    <motor name="joint1act" joint="joint1"/>
    <motor name="joint2act" joint="joint2"/>
    <motor name="jnt_end0act" joint="jnt_end0"/>
    <motor name="joint4act" joint="joint4"/>
    <motor name="joint5act" joint="joint5"/>
    <motor name="jnt_end1act" joint="jnt_end1"/>
    <velocity name="t0v" joint="t0" gear="1 0 0 0 0 0"/>
    <velocity name="t1v" joint="t1"/>
  </actuator>

</mujoco>